Workbook

Sheet Instructions
A1: Brucellosis Control Cost-Benefit Analysis — Worked Workbook (with formulas)
B3: Purpose
B4: This workbook is the formula version of the brucellosis control cost-benefit exercise: comparing a vaccination program against a test-and-slaughter program for controlling B. melitensis in sheep and goats, over an 8-year period. Every answer cell holds a live Excel formula, so you can click any yellow cell to see how it is calculated, or change an input and watch the results update.
B6: How to use this worksheet
B7: 1. "Cost & Benefit Estimation" sheet — shows where the Year 1–3 costs and benefits come from (vaccination cost, test-and-slaughter cost, avoided human cases, avoided animal losses). Check rows compare each result with the published figure.
B8: 2. "Strategy A - Vaccination" sheet — net value, discount factor, discounted cost and benefit, NPV per year, and cumulative NPV. The gold cell (C3) is the interest rate, 7.74%.
B9: 3. "Strategy B - Test-and-Slaughter" sheet — the same calculations for test-and-slaughter. Each strategy sheet has its own rate cell (C3); change both if you test another rate.
B10: 4. "Summary" sheet — the six comparison metrics link to the strategy sheets, and the two decision answers are chosen by formula (higher BCR for Q1, higher NPV for Q2).
B11: 5. Try it: change the rate, coverage, prevalence or a unit cost and see whether the decisions change.
B13: Colour guide
B14: Blue cell — given data. These are the numbers you need; do not edit them.
B15: Gold cell — key assumption (the interest rate). Already set for you.
B16: Yellow cell — calculated answer. Contains a formula; click it to see how it works.
... B26: Hadzovic, D., Fejzic, N., Seric-Haracic, S., van Asseldonk, M., & Bergevoet, R.H.M. (2025). Cost-benefit analysis of the small ruminants vaccination program against brucellosis (B. melitensis) in Bosnia and Herzegovina. Acta Veterinaria Eurasia, 51, 0082.

Sheet Cost & Benefit Estimation
A1: Before You Start - Cost & Benefit Estimation (Years 1-3)
A2: Shows where the Year 1-3 figures in the Strategy sheets come from. Change any blue input and every yellow cell recalculates.
C3: Given data | D3: Calculated
A5: 1. GIVEN INPUTS
A6: Item | B6: Unit | C6: Value | F6: Hint / source
A7: Population
A8: Sheep population | B8: head | C8: 830000
A9: Goat population | B9: head | C9: 53000
A10: Vaccination program - per-animal costs
A11: Vaccine cost per animal | B11: EUR/head | C11: 0.135
A12: Veterinary / administration cost per animal | B12: EUR/head | C12: 1.55
A13: Other cost per animal | B13: EUR/head | C13: 0.1
A14: Share of population sampled & tested alongside vaccination | B14: % | C14: 0.05
A15: Sampling & testing (both strategies)
A16: Sampling cost per animal tested | B16: EUR/head | C16: 2.55
A17: Testing cost per animal tested | B17: EUR/head | C17: 2.55
A18: Test-and-slaughter
A19: Share of population sampled, tested & culled each year | B19: % | C19: 0.5
A20: Replacement cost per culled animal | B20: EUR/head | C20: 120
A21: Destruction cost per culled animal | B21: EUR/head | C21: 10
A22: Prevalence in Year 1 | B22: % | C22: 0.045 | F22: From the epidemiological model.
A23: Annual fall in prevalence under test-and-slaughter | B23: % | C23: 0.375 | F23: Prevalence each year = previous year x (1 - this rate).
A24: Human case costs
A25: Income loss due to sick leave | B25: EUR/case | C25: 700
A26: Hospitalization | B26: EUR/case | C26: 450
A27: Treatment / medication | B27: EUR/case | C27: 500
A28: Other family costs | B28: EUR/case | C28: 300
A29: Animal production losses
A30: Reduction in reproduction from infection | B30: % | C30: 0.322
A31: Reduction in milk yield from infection | B31: % | C31: 0.15
A32: Reproduction rate - sheep | B32: lambs/ewe/yr | C32: 1.2
A33: Reproduction rate - goats | B33: kids/doe/yr | C33: 1.5
A34: Price per lamb | B34: EUR/head | C34: 80
A35: Price per kid | B35: EUR/head | C35: 90
A36: Milk yield - sheep | B36: L/ewe/yr | C36: 60
A37: Milk yield - goats | B37: L/doe/yr | C37: 115
A38: Milk price - sheep | B38: EUR/L | C38: 0.609
A39: Milk price - goats | B39: EUR/L | C39: 1.307
A41: 2. COST ESTIMATION - VACCINATION PROGRAM
A42: Item | B42: Unit | C42: Year 1 | D42: Year 2 | E42: Year 3 | F42: Hint / source
...

Sheet Strategy A - Vaccination
A1: Strategy A - Vaccination
A3: Interest rate used for discounting (r): | C3: 0.0774
B5: Given data | E5: Key assumption | H5: Calculated (formula)
A7: Item | B7: Unit | C7: Year 1 | D7: Year 2 | E7: Year 3 | F7: Year 4 | G7: Year 5 | H7: Year 6 | I7: Year 7 | J7: Year 8 | K7: Total | L7: Hint (how to calculate)
A8: 1. GIVEN DATA (EUR)
A9: Total annual cost | B9: EUR/yr | C9: 1835602 | D9: 656048 | E9: 603048 | F9: 603048 | G9: 603048 | H9: 603048 | I9: 603048 | J9: 603049 | K9: =SUM(C9:J9) -> 6109939
A10: Total annual benefit | B10: EUR/yr | C10: 823348 | D10: 2260101 | E10: 3629271 | F10: 5008894 | G10: 6470455 | H10: 8084010 | I10: 9922737 | J10: 12067258 | K10: =SUM(C10:J10) -> 48266074
A12: 2. NET VALUE & DISCOUNTED CASH FLOW (EUR)
A13: Net value (undiscounted) | B13: EUR/yr | C13: =C10-C9 -> -1012254 | D13: =D10-D9 -> 1604053 | E13: =E10-E9 -> 3026223 | F13: =F10-F9 -> 4405846 | G13: =G10-G9 -> 5867407 | H13: =H10-H9 -> 7480962 | I13: =I10-I9 -> 9319689 | J13: =J10-J9 -> 11464209 | K13: =SUM(C13:J13) -> 42156135 | L13: Total annual benefit − total annual cost.
A14: Discount factor (r = 7.74%) | B14: — | C14: =1/(1+$C$3)^0 -> 1 | D14: =1/(1+$C$3)^1 -> 0.92816039 | E14: =1/(1+$C$3)^2 -> 0.8614817 | F14: =1/(1+$C$3)^3 -> 0.79959319 | G14: =1/(1+$C$3)^4 -> 0.74215072 | H14: =1/(1+$C$3)^5 -> 0.6888349 | I14: =1/(1+$C$3)^6 -> 0.63934927 | J14: =1/(1+$C$3)^7 -> 0.59341866 | K14: — | L14: 1 ÷ (1 + r)^t, using the rate in 'Strategy A - Vaccination'!$C$3. t = year number − 1. No total for this row.
A15: Discounted cost | B15: EUR/yr | C15: =C9*C14 -> 1835602 | D15: =D9*D14 -> 608917.76 | E15: =E9*E14 -> 519514.82 | F15: =F9*F14 -> 482193.07 | G15: =G9*G14 -> 447552.51 | H15: =H9*H14 -> 415400.51 | I15: =I9*I14 -> 385558.3 | J15: =J9*J14 -> 357860.53 | K15: =SUM(C15:J15) -> 5052599.5 | L15: Total annual cost × discount factor.
A16: Discounted benefit | B16: EUR/yr | C16: =C10*C14 -> 823348 | D16: =D10*D14 -> 2097736.2 | E16: =E10*E14 -> 3126550.6 | F16: =F10*F14 -> 4005077.5 | G16: =G10*G14 -> 4802052.9 | H16: =H10*H14 -> 5568548.2 | I16: =I10*I14 -> 6344094.6 | J16: =J10*J14 -> 7160936.1 | K16: =SUM(C16:J16) -> 33928344 | L16: Total annual benefit × discount factor.
A17: Net present value (per year) | B17: EUR/yr | C17: =C16-C15 -> -1012254 | D17: =D16-D15 -> 1488818.5 | E17: =E16-E15 -> 2607035.7 | F17: =F16-F15 -> 3522884.5 | G17: =G16-G15 -> 4354500.4 | H17: =H16-H15 -> 5153147.7 | I17: =I16-I15 -> 5958536.3 | J17: =J16-J15 -> 6803075.6 | K17: =SUM(C17:J17) -> 28875745 | L17: Discounted benefit − discounted cost.
A18: Cumulative NPV | B18: EUR | C18: =C17 -> -1012254 | D18: =C18+D17 -> 476564.45 | E18: =D18+E17 -> 3083600.2 | F18: =E18+F17 -> 6606484.6 | G18: =F18+G17 -> 10960985 | H18: =G18+H17 -> 16114133 | I18: =H18+I17 -> 22072669 | J18: =I18+J17 -> 28875745 | K18: =J18 -> 28875745 | L18: Running sum of NPV per year. Total should match the final year’s cumulative value.

Sheet Strategy B - Test-and-Slaughter
A1: Strategy B - Test-and-Slaughter
A3: Interest rate used for discounting (r): | C3: 0.0774
B5: Given data | E5: Key assumption | H5: Calculated (formula)
A7: Item | B7: Unit | C7: Year 1 | D7: Year 2 | E7: Year 3 | F7: Year 4 | G7: Year 5 | H7: Year 6 | I7: Year 7 | J7: Year 8 | K7: Total | L7: Hint (how to calculate)
A8: 1. GIVEN DATA (EUR)
A9: Total annual cost | B9: EUR/yr | C9: 4834425 | D9: 3865884 | E9: 3260546 | F9: 2882210 | G9: 2645750 | H9: 2497963 | I9: 2405595 | J9: 2347866 | K9: =SUM(C9:J9) -> 24740239
A10: Total annual benefit | B10: EUR/yr | C10: 823348 | D10: 4283189 | E10: 6985968 | F10: 9734670 | G10: 12614800 | H10: 15834289 | I10: 19588968 | J10: 24082167 | K10: =SUM(C10:J10) -> 93947399
A12: 2. NET VALUE & DISCOUNTED CASH FLOW (EUR)
A13: Net value (undiscounted) | B13: EUR/yr | C13: =C10-C9 -> -4011077 | D13: =D10-D9 -> 417305 | E13: =E10-E9 -> 3725422 | F13: =F10-F9 -> 6852460 | G13: =G10-G9 -> 9969050 | H13: =H10-H9 -> 13336326 | I13: =I10-I9 -> 17183373 | J13: =J10-J9 -> 21734301 | K13: =SUM(C13:J13) -> 69207160 | L13: Total annual benefit − total annual cost.
A14: Discount factor (r = 7.74%) | B14: — | C14: =1/(1+$C$3)^0 -> 1 | D14: =1/(1+$C$3)^1 -> 0.92816039 | E14: =1/(1+$C$3)^2 -> 0.8614817 | F14: =1/(1+$C$3)^3 -> 0.79959319 | G14: =1/(1+$C$3)^4 -> 0.74215072 | H14: =1/(1+$C$3)^5 -> 0.6888349 | I14: =1/(1+$C$3)^6 -> 0.63934927 | J14: =1/(1+$C$3)^7 -> 0.59341866 | K14: — | L14: 1 ÷ (1 + r)^t, using the rate in 'Strategy B - Test-and-Slaughter'!$C$3. t = year number − 1. No total for this row.
A15: Discounted cost | B15: EUR/yr | C15: =C9*C14 -> 4834425 | D15: =D9*D14 -> 3588160.4 | E15: =E9*E14 -> 2808900.7 | F15: =F9*F14 -> 2304595.5 | G15: =G9*G14 -> 1963545.3 | H15: =H9*H14 -> 1720684.1 | I15: =I9*I14 -> 1538015.4 | J15: =J9*J14 -> 1393267.5 | K15: =SUM(C15:J15) -> 20151594 | L15: Total annual cost × discount factor.
A16: Discounted benefit | B16: EUR/yr | C16: =C10*C14 -> 823348 | D16: =D10*D14 -> 3975486.4 | E16: =E10*E14 -> 6018283.6 | F16: =F10*F14 -> 7783775.8 | G16: =G10*G14 -> 9362082.9 | H16: =H10*H14 -> 10907211 | I16: =I10*I14 -> 12524192 | J16: =J10*J14 -> 14290807 | K16: =SUM(C16:J16) -> 65685187 | L16: Total annual benefit × discount factor.
A17: Net present value (per year) | B17: EUR/yr | C17: =C16-C15 -> -4011077 | D17: =D16-D15 -> 387325.97 | E17: =E16-E15 -> 3209382.9 | F17: =F16-F15 -> 5479180.3 | G17: =G16-G15 -> 7398537.7 | H17: =H16-H15 -> 9186526.8 | I17: =I16-I15 -> 10986177 | J17: =J16-J15 -> 12897540 | K17: =SUM(C17:J17) -> 45533594 | L17: Discounted benefit − discounted cost.
A18: Cumulative NPV | B18: EUR | C18: =C17 -> -4011077 | D18: =C18+D17 -> -3623751 | E18: =D18+E17 -> -414368.14 | F18: =E18+F17 -> 5064812.2 | G18: =F18+G17 -> 12463350 | H18: =G18+H17 -> 21649877 | I18: =H18+I17 -> 32636054 | J18: =I18+J17 -> 45533594 | K18: =J18 -> 45533594 | L18: Running sum of NPV per year. Total should match the final year’s cumulative value.

Sheet Summary
A1: Summary: Compare the Two Strategies
C3: Yellow cell = calculated (formula)
A5: Metric | B5: Vaccination | C5: Test-and-Slaughter | D5: Hint
A6: Total cost (undiscounted, 8-yr) | B6: ='Strategy A - Vaccination'!K9 -> 6109939 | C6: ='Strategy B - Test-and-Slaughter'!K9 -> 24740239 | D6: Total column, Total annual cost row on each strategy's sheet.
A7: Total benefit (undiscounted, 8-yr) | B7: ='Strategy A - Vaccination'!K10 -> 48266074 | C7: ='Strategy B - Test-and-Slaughter'!K10 -> 93947399 | D7: Total column, Total annual benefit row on each strategy's sheet.
A8: Total discounted cost | B8: ='Strategy A - Vaccination'!K15 -> 5052599.5 | C8: ='Strategy B - Test-and-Slaughter'!K15 -> 20151594 | D8: Total column, Discounted cost row.
A9: Total discounted benefit | B9: ='Strategy A - Vaccination'!K16 -> 33928344 | C9: ='Strategy B - Test-and-Slaughter'!K16 -> 65685187 | D9: Total column, Discounted benefit row.
A10: Net present value – NPV | B10: ='Strategy A - Vaccination'!K17 -> 28875745 | C10: ='Strategy B - Test-and-Slaughter'!K17 -> 45533594 | D10: Sum of NPV per year (= final cumulative NPV).
A11: Cost-benefit ratio – BCR | B11: =B9/B8 -> 6.7150274 | C11: =C9/C8 -> 3.259553 | D11: Total discounted benefit ÷ total discounted cost.
A13: 3. DECISION
A14: Q1. Limited budget — which strategy offers better value for money? | B14: =IF(B11>C11,"Vaccination","Test-and-Slaughter") -> Vaccination | C14: Picks the strategy with the higher BCR (value per euro spent).
A15: Q2. No budget constraint — which strategy gives the largest NPV? | B15: =IF(B10>C10,"Vaccination","Test-and-Slaughter") -> Test-and-Slaughter | C15: Picks the strategy with the higher total NPV (largest absolute gain).
